{"uuid": "427bd9e0-6a7f-4f9e-924a-b304fd7b140c", "children": ["6d7657ab-f222-40de-ab5e-0d5e7228358e"], "befores": [{"name": "_xunit_setup_method_fixture_TestLogin", "status": "broken", "statusDetails": {"message": "selenium.common.exceptions.WebDriverException: Message: An unknown server-side error occurred while processing the command. Original error: Cannot verify the signature of 'C:\\Users\\Administrator\\AppData\\Local\\Programs\\Appium\\resources\\app\\node_modules\\appium\\node_modules\\appium-uiautomator2-server\\apks\\appium-uiautomator2-server-v4.17.4.apk'. Original error: Java HotSpot(TM) 64-Bit Server VM warning: INFO: os::commit_memory(0x00000000c0000000, 134217728, 0) failed; error='ҳ���ļ�̫С���޷���ɲ�����' (DOS error/errno=1455)\n\nStacktrace:\nUnknownError: An unknown server-side error occurred while processing the command. Original error: Cannot verify the signature of 'C:\\Users\\Administrator\\AppData\\Local\\Programs\\Appium\\resources\\app\\node_modules\\appium\\node_modules\\appium-uiautomator2-server\\apks\\appium-uiautomator2-server-v4.17.4.apk'. Original error: Java HotSpot(TM) 64-Bit Server VM warning: INFO: os::commit_memory(0x00000000c0000000, 134217728, 0) failed; error='ҳ���ļ�̫С���޷���ɲ�����' (DOS error/errno=1455)\n\n    at getResponseForW3CError (C:\\Users\\Administrator\\AppData\\Local\\Programs\\Appium\\resources\\app\\node_modules\\appium\\node_modules\\appium-base-driver\\lib\\protocol\\errors.js:804:9)\n    at asyncHandler (C:\\Users\\Administrator\\AppData\\Local\\Programs\\Appium\\resources\\app\\node_modules\\appium\\node_modules\\appium-base-driver\\lib\\protocol\\protocol.js:380:37)\n", "trace": "  File \"E:\\python_workspace\\AppiumProject\\venv\\lib\\site-packages\\pluggy\\_callers.py\", line 39, in _multicall\n    res = hook_impl.function(*args)\n  File \"E:\\python_workspace\\AppiumProject\\venv\\lib\\site-packages\\_pytest\\fixtures.py\", line 1130, in pytest_fixture_setup\n    result = call_fixture_func(fixturefunc, request, kwargs)\n  File \"E:\\python_workspace\\AppiumProject\\venv\\lib\\site-packages\\_pytest\\fixtures.py\", line 902, in call_fixture_func\n    fixture_result = next(generator)\n  File \"E:\\python_workspace\\AppiumProject\\venv\\lib\\site-packages\\_pytest\\python.py\", line 907, in xunit_setup_method_fixture\n    _call_with_optional_argument(func, method)\n  File \"E:\\python_workspace\\AppiumProject\\venv\\lib\\site-packages\\_pytest\\python.py\", line 787, in _call_with_optional_argument\n    func()\n  File \"E:\\python_workspace\\AppiumProject\\MainProject\\testcases\\TestLogin.py\", line 35, in setup\n    self.driver = webdriver.Remote(\"http://127.0.0.1:4723/wd/hub\", data[\"desired_caps\"])\n  File \"E:\\python_workspace\\AppiumProject\\venv\\lib\\site-packages\\appium\\webdriver\\webdriver.py\", line 257, in __init__\n    super().__init__(\n  File \"E:\\python_workspace\\AppiumProject\\venv\\lib\\site-packages\\selenium\\webdriver\\remote\\webdriver.py\", line 206, in __init__\n    self.start_session(capabilities)\n  File \"E:\\python_workspace\\AppiumProject\\venv\\lib\\site-packages\\appium\\webdriver\\webdriver.py\", line 346, in start_session\n    response = self.execute(RemoteCommand.NEW_SESSION, w3c_caps)\n  File \"E:\\python_workspace\\AppiumProject\\venv\\lib\\site-packages\\selenium\\webdriver\\remote\\webdriver.py\", line 346, in execute\n    self.error_handler.check_response(response)\n  File \"E:\\python_workspace\\AppiumProject\\venv\\lib\\site-packages\\selenium\\webdriver\\remote\\errorhandler.py\", line 245, in check_response\n    raise exception_class(message, screen, stacktrace)\n"}, "start": 1687859069071, "stop": 1687859072183}], "start": 1687859069071, "stop": 1687859072643}